<?xml version="0.0" ?>
<robot name="RC_car">
    <link name="carbody">
    <inertial>
        <origin rpy="0 0 0" xyz="0 0 0"/>
        <mass value="5.0"/>
        <inertia ixx="0.1" ixy="0" ixz="0" iyy="0.1" iyz="0" izz="0.1"/>
    </inertial>
    <visual>
        <origin rpy="0 0 0" xyz="0 0 0"/>
        <geometry>
          <box size="0.32 0.2 0.1"/>
        </geometry>
	      <material name="blue">
      	    <color rgba="0.4 0.4 0.8 1" />
	      </material>
    </visual>
    <collision>
        <origin rpy="0 0 0" xyz="0 0 0"/>
        <geometry>
            <box size="0.32 0.2 0.1"/>
        </geometry>
    </collision>
    </link>


  <link name="wheelLF">
    <inertial>
      <origin rpy="-1.57454489647697 0 0" xyz="0 0 0"/>
       <mass value="0.1"/>
       <inertia ixx="0.1" ixy="0" ixz="0" iyy="0.1" iyz="0" izz="0.1"/>
    </inertial>

    <visual>
      <origin rpy="-1.57454489647697 0 0 " xyz="0 0 0"/>
      <geometry>
        <cylinder radius="0.06" length="0.03"/>
      </geometry>
      <material name="white">
        <color rgba="0.2 0.2 0.2 1" />
      </material>
    </visual>
    <collision>
      <origin rpy="-1.57454489647697 0 0 " xyz="0 0 0"/>
      <geometry>
        <cylinder radius="0.06" length="0.03"/>
      </geometry>
    </collision>
  </link>


<link name="wheelRF">
    <inertial>
      <origin rpy="1.57454489647697 0 0" xyz="0 0 0"/>
       <mass value="0.1"/>
       <inertia ixx="0.1" ixy="0" ixz="0" iyy="0.1" iyz="0" izz="0.1"/>
    </inertial>
    <visual>
      <origin rpy="1.57454489647697 0 0 " xyz="0 0 0"/>
      <geometry>
        <cylinder radius="0.06" length="0.03"/>
      </geometry>
      <material name="white">
        <color rgba="0.2 0.2 0.2 1" />
      </material>
    </visual>
    <collision>
      <origin rpy="1.57454489647697 0 0 " xyz="0 0 0"/>
      <geometry>
        <cylinder radius="0.06" length="0.03"/>
      </geometry>
    </collision>
  </link>


<link name="wheelLB">
    <inertial>
      <origin rpy="-1.57454489647697 0 0" xyz="0 0 0"/>
       <mass value="0.1"/>
       <inertia ixx="0.1" ixy="0" ixz="0" iyy="0.1" iyz="0" izz="0.1"/>
    </inertial>
    <visual>
      <origin rpy="-1.57454489647697 0 0 " xyz="0 0 0"/>
      <geometry>
        <cylinder radius="0.06" length="0.03"/>
      </geometry>
      <material name="white">
        <color rgba="0.2 0.2 0.2 1" />
      </material>
    </visual>
    <collision>
      <origin rpy="-1.57454489647697 0 0 " xyz="0 0 0"/>
      <geometry>
        <cylinder radius="0.06" length="0.03"/>
      </geometry>
    </collision>
  </link>

<link name="wheelRB">
    <inertial>
      <origin rpy="1.57454489647697 0 0" xyz="0 0 0"/>
       <mass value="0.1"/>
       <inertia ixx="0.1" ixy="0" ixz="0" iyy="0.1" iyz="0" izz="0.1"/>
    </inertial>
    <visual>
      <origin rpy="1.57454489647697 0 0 " xyz="0 0 0"/>
      <geometry>
        <cylinder radius="0.06" length="0.03"/>
      </geometry>
      <material name="white">
        <color rgba="0.2 0.2 0.2 1" />
      </material>
    </visual>
    <collision>
      <origin rpy="1.57454489647697 0 0 " xyz="0 0 0"/>
      <geometry>
        <cylinder radius="0.06" length="0.03"/>
      </geometry>
    </collision>
</link>

<link name="LF_steering">
  <inertial>
    <origin xyz="0.0 0.0 0.0" rpy="0.0 0.0 0.0"/>
    <mass value="0.0"/>
    <inertia ixx="0.0" ixy="0.0" ixz="0.0" iyy="0.0" iyz="0.0" izz="0.0"/>
  </inertial>
  <visual name="lfs">
    <origin xyz="0.0 0.0 0.0" rpy="0.0 0.0 0.0"/>
    <geometry>
      <box size="0.0 0.0 0.0"/>
    </geometry>
  </visual>
</link>

<link name="RF_steering">
  <inertial>
    <origin xyz="0.0 0.0 0.0" rpy="0.0 0.0 0.0"/>
    <mass value="0.0"/>
    <inertia ixx="0.0" ixy="0.0" ixz="0.0" iyy="0.0" iyz="0.0" izz="0.0"/>
  </inertial>
  <visual name="rfs">
    <origin xyz="0.0 0.0 0.0" rpy="0.0 0.0 0.0"/>
    <geometry>
      <box size="0.0 0.0 0.0"/>
    </geometry>
  </visual>
</link>

  <joint name="0LF" type="continuous">
    <axis xyz="0 1 0"/>
    <parent link="LF_steering"/>
    <child link="wheelLF"/>
    <origin rpy="0 0 0" xyz="0 0 0"/>
    <limit effort="100" velocity="100"/>
    <joint_properties damping="0.0" friction="0.05"/>
  </joint>
  
  <joint name="1RF" type="continuous">
    <axis xyz="0 1 0"/>
    <parent link="RF_steering"/>
    <child link="wheelRF"/>
    <origin rpy="0 0 0" xyz="0 0 0"/>
    <limit effort="100" velocity="100"/>
    <joint_properties damping="0.0" friction="0.05"/>
  </joint>

  <joint name="2LB" type="continuous">
    <axis xyz="0 1 0"/>
    <parent link="carbody"/>
    <child link="wheelLB"/>
    <origin rpy="0 0 0" xyz="-0.15, 0.13, -0.04"/>
    <limit effort="100" velocity="100"/>
    <joint_properties damping="0.0" friction="0.05"/>
  </joint>

  <joint name="3RB" type="continuous">
    <axis xyz="0 1 0"/>
    <parent link="carbody"/>
    <child link="wheelRB"/>
    <origin rpy="0 0 0" xyz="-0.15, -0.13, -0.04"/>
    <limit effort="100" velocity="100"/>
    <joint_properties damping="0.0" friction="0.05"/>
  </joint>

  <joint name="4LFS" type="revolute">
    <origin xyz="0.15, 0.13, -0.04" rpy="0 0 0"/>
    <parent link="carbody"/>
    <child link="LF_steering"/>
    <axis xyz="0.0 0.0 1.0"/>
    <limit lower="-0.523" upper="0.523" effort="50.0" velocity="20.0"/>
  </joint>

  <joint name="5RFS" type="revolute">
    <origin xyz="0.15, -0.13, -0.04" rpy="0 0 0"/>
    <parent link="carbody"/>
    <child link="RF_steering"/>
    <axis xyz="0.0 0.0 1.0"/>
    <limit lower="-0.523" upper="0.523" effort="50.0" velocity="20.0"/>
  </joint>

</robot>